Workbook

Sheet ⚙️ Настройки
A1: ⚙️ НАСТРОЙКИ И ПАРАМЕТРЫ
A3: 👤 УЧАСТНИКИ
A4: Имя 1 | B4: User1
A5: Имя 2 | B5: User2
A7: 💰 ДОХОДЫ (руб/мес)
A8: Зарплата User1 | B8: 120000
A9: Доп. доход User1 | B9: 10000
A10: Зарплата User2 | B10: 90000
A11: Доп. доход User2 | B11: 0
A12: Итого User1 | B12: =B8+B9
A13: Итого User2 | B13: =B10+B11
A14: Итого семья | B14: =B12+B13
A15: Доля User1 % | B15: =IFERROR(B12/B14,0.5)
A16: Доля User2 % | B16: =IFERROR(B13/B14,0.5)
A18: 🎛️ ПАРАМЕТРЫ НАКОПЛЕНИЙ
A19: % откладывания от остатка | B19: 0.5
A20: Курс доллара, руб | B20: 90
A21: Курс евро, руб | B21: 98
A22: Подушка безопасности (мес) | B22: 6
A25: 🏷️ КАТЕГОРИИ РАСХОДОВ | C25: 🏦 СЧЕТА И ВКЛАДЫ
A26: Еда и продукты | C26: Main Card
A27: Кредиты | C27: Family Card
A28: Ипотека | C28: Savings
A29: Коммунальные
A30: Транспорт
A31: Бензин
A32: Дом
A33: Платежи/подписки
A34: User1 личное
A35: User2 личное
A36: Развлечения
A37: Подарки
A38: Путешествия
A39: Одежда
A40: Здоровье
... A47: 💼 РАСЧЁТ ЗАРПЛАТЫ ПО РАБОЧИМ ДНЯМ
A48: Расчётный месяц → | B48: 2026-05 | C48: ← введи нужный месяц (ГГГГ-ММ)
A49: Рабочих дней 1 – 15 | B49: =IFERROR(NETWORKDAYS(DATE(LEFT(B48,4)*1,RIGHT(B48,2)*1,1),DATE(LEFT(B48,4)*1,RIGHT(B48,2)*1,15)),0)
A50: Рабочих дней 16 – конец | B50: =IFERROR(NETWORKDAYS(DATE(LEFT(B48,4)*1,RIGHT(B48,2)*1,16),EOMONTH(DATE(LEFT(B48,4)*1,RIGHT(B48,2)*1,1),0)),0)
A51: Итого рабочих дней | B51: =B49+B50
...

Sheet 📋 Транзакции
A1: 📋 ЖУРНАЛ ТРАНЗАКЦИЙ
A2: Дата | B2: Месяц | C2: Описание | D2: Категория | E2: Тип | F2: Чья | G2: Сумма, ₽ | H2: Счёт | I2: Обязат.? | J2: Доля User1 | K2: Доля User2
A3: 46113 | B3: =IF(ISNUMBER(A3),YEAR(A3)&"-"&TEXT(MONTH(A3),"00"),"") | C3: Grocery store | D3: Еда и продукты | E3: Расход | F3: Общее | G3: 5200 | H3: Main Card | I3: Нет | J3: =IF(G3="","",IF(F3="User1",G3,IF(F3="User2",0,IF(I3="Да",G3*'⚙️ Настройки'!B15,G3*0.5)))) | K3: =IF(G3="","",IF(F3="User2",G3,IF(F3="User1",0,IF(I3="Да",G3*'⚙️ Настройки'!B16,G3*0.5))))
A4: 46115 | B4: =IF(ISNUMBER(A4),YEAR(A4)&"-"&TEXT(MONTH(A4),"00"),"") | C4: Salary User1 | D4: Доход | E4: Доход | F4: User1 | G4: 120000 | H4: Main Card | I4: Нет | J4: =IF(G4="","",IF(F4="User1",G4,IF(F4="User2",0,IF(I4="Да",G4*'⚙️ Настройки'!B15,G4*0.5)))) | K4: =IF(G4="","",IF(F4="User2",G4,IF(F4="User1",0,IF(I4="Да",G4*'⚙️ Настройки'!B16,G4*0.5))))
A5: 46117 | B5: =IF(ISNUMBER(A5),YEAR(A5)&"-"&TEXT(MONTH(A5),"00"),"") | C5: Mortgage payment | D5: Ипотека | E5: Расход | F5: Общее | G5: 35000 | H5: Main Card | I5: Да | J5: =IF(G5="","",IF(F5="User1",G5,IF(F5="User2",0,IF(I5="Да",G5*'⚙️ Настройки'!B15,G5*0.5)))) | K5: =IF(G5="","",IF(F5="User2",G5,IF(F5="User1",0,IF(I5="Да",G5*'⚙️ Настройки'!B16,G5*0.5))))
A6: 46119 | B6: =IF(ISNUMBER(A6),YEAR(A6)&"-"&TEXT(MONTH(A6),"00"),"") | C6: Coffee | D6: Еда и продукты | E6: Расход | F6: User1 | G6: 450 | H6: Main Card | I6: Нет | J6: =IF(G6="","",IF(F6="User1",G6,IF(F6="User2",0,IF(I6="Да",G6*'⚙️ Настройки'!B15,G6*0.5)))) | K6: =IF(G6="","",IF(F6="User2",G6,IF(F6="User1",0,IF(I6="Да",G6*'⚙️ Настройки'!B16,G6*0.5))))
A7: 46121 | B7: =IF(ISNUMBER(A7),YEAR(A7)&"-"&TEXT(MONTH(A7),"00"),"") | C7: Gas station | D7: Бензин | E7: Расход | F7: User2 | G7: 3200 | H7: Family Card | I7: Нет | J7: =IF(G7="","",IF(F7="User1",G7,IF(F7="User2",0,IF(I7="Да",G7*'⚙️ Настройки'!B15,G7*0.5)))) | K7: =IF(G7="","",IF(F7="User2",G7,IF(F7="User1",0,IF(I7="Да",G7*'⚙️ Настройки'!B16,G7*0.5))))
A8: 46122 | B8: =IF(ISNUMBER(A8),YEAR(A8)&"-"&TEXT(MONTH(A8),"00"),"") | C8: Internet | D8: Коммунальные | E8: Расход | F8: Общее | G8: 900 | H8: Main Card | I8: Да | J8: =IF(G8="","",IF(F8="User1",G8,IF(F8="User2",0,IF(I8="Да",G8*'⚙️ Настройки'!B15,G8*0.5)))) | K8: =IF(G8="","",IF(F8="User2",G8,IF(F8="User1",0,IF(I8="Да",G8*'⚙️ Настройки'!B16,G8*0.5))))
A9: 46124 | B9: =IF(ISNUMBER(A9),YEAR(A9)&"-"&TEXT(MONTH(A9),"00"),"") | C9: Pharmacy | D9: Здоровье | E9: Расход | F9: User2 | G9: 1800 | H9: Family Card | I9: Нет | J9: =IF(G9="","",IF(F9="User1",G9,IF(F9="User2",0,IF(I9="Да",G9*'⚙️ Настройки'!B15,G9*0.5)))) | K9: =IF(G9="","",IF(F9="User2",G9,IF(F9="User1",0,IF(I9="Да",G9*'⚙️ Настройки'!B16,G9*0.5))))
A10: 46127 | B10: =IF(ISNUMBER(A10),YEAR(A10)&"-"&TEXT(MONTH(A10),"00"),"") | C10: AI subscription | D10: Платежи/подписки | E10: Расход | F10: Общее | G10: 1990 | H10: Main Card | I10: Да | J10: =IF(G10="","",IF(F10="User1",G10,IF(F10="User2",0,IF(I10="Да",G10*'⚙️ Настройки'!B15,G10*0.5)))) | K10: =IF(G10="","",IF(F10="User2",G10,IF(F10="User1",0,IF(I10="Да",G10*'⚙️ Настройки'!B16,G10*0.5))))
A11: 46132 | B11: =IF(ISNUMBER(A11),YEAR(A11)&"-"&TEXT(MONTH(A11),"00"),"") | C11: Salary User2 | D11: Доход | E11: Доход | F11: User2 | G11: 90000 | H11: Family Card | I11: Нет | J11: =IF(G11="","",IF(F11="User1",G11,IF(F11="User2",0,IF(I11="Да",G11*'⚙️ Настройки'!B15,G11*0.5)))) | K11: =IF(G11="","",IF(F11="User2",G11,IF(F11="User1",0,IF(I11="Да",G11*'⚙️ Настройки'!B16,G11*0.5))))
A12: 46133 | B12: =IF(ISNUMBER(A12),YEAR(A12)&"-"&TEXT(MONTH(A12),"00"),"") | C12: Family dinner | D12: Развлечения | E12: Расход | F12: Общее | G12: 4300 | H12: Main Card | I12: Нет | J12: =IF(G12="","",IF(F12="User1",G12,IF(F12="User2",0,IF(I12="Да",G12*'⚙️ Настройки'!B15,G12*0.5)))) | K12: =IF(G12="","",IF(F12="User2",G12,IF(F12="User1",0,IF(I12="Да",G12*'⚙️ Настройки'!B16,G12*0.5))))
A13: 46135 | B13: =IF(ISNUMBER(A13),YEAR(A13)&"-"&TEXT(MONTH(A13),"00"),"") | C13: Taxi | D13: Транспорт | E13: Расход | F13: User1 | G13: 780 | H13: Main Card | I13: Нет | J13: =IF(G13="","",IF(F13="User1",G13,IF(F13="User2",0,IF(I13="Да",G13*'⚙️ Настройки'!B15,G13*0.5)))) | K13: =IF(G13="","",IF(F13="User2",G13,IF(F13="User1",0,IF(I13="Да",G13*'⚙️ Настройки'!B16,G13*0.5))))
A14: 46137 | B14: =IF(ISNUMBER(A14),YEAR(A14)&"-"&TEXT(MONTH(A14),"00"),"") | C14: Online course | D14: Саморазвитие | E14: Расход | F14: User2 | G14: 12000 | H14: Family Card | I14: Нет | J14: =IF(G14="","",IF(F14="User1",G14,IF(F14="User2",0,IF(I14="Да",G14*'⚙️ Настройки'!B15,G14*0.5)))) | K14: =IF(G14="","",IF(F14="User2",G14,IF(F14="User1",0,IF(I14="Да",G14*'⚙️ Настройки'!B16,G14*0.5))))
A15: 46139 | B15: =IF(ISNUMBER(A15),YEAR(A15)&"-"&TEXT(MONTH(A15),"00"),"") | C15: Gift for friend | D15: Подарки | E15: Расход | F15: User1 | G15: 3500 | H15: Main Card | I15: Нет | J15: =IF(G15="","",IF(F15="User1",G15,IF(F15="User2",0,IF(I15="Да",G15*'⚙️ Настройки'!B15,G15*0.5)))) | K15: =IF(G15="","",IF(F15="User2",G15,IF(F15="User1",0,IF(I15="Да",G15*'⚙️ Настройки'!B16,G15*0.5))))
A16: 46140 | B16: =IF(ISNUMBER(A16),YEAR(A16)&"-"&TEXT(MONTH(A16),"00"),"") | C16: Home supplies | D16: Дом | E16: Расход | F16: Общее | G16: 2400 | H16: Family Card | I16: Нет | J16: =IF(G16="","",IF(F16="User1",G16,IF(F16="User2",0,IF(I16="Да",G16*'⚙️ Настройки'!B15,G16*0.5)))) | K16: =IF(G16="","",IF(F16="User2",G16,IF(F16="User1",0,IF(I16="Да",G16*'⚙️ Настройки'!B16,G16*0.5))))
A17: 46142 | B17: =IF(ISNUMBER(A17),YEAR(A17)&"-"&TEXT(MONTH(A17),"00"),"") | C17: Card transfer between accounts | D17: Перевод | E17: Перевод | F17: User1 | G17: 10000 | H17: Savings | I17: Нет | J17: =IF(G17="","",IF(F17="User1",G17,IF(F17="User2",0,IF(I17="Да",G17*'⚙️ Настройки'!B15,G17*0.5)))) | K17: =IF(G17="","",IF(F17="User2",G17,IF(F17="User1",0,IF(I17="Да",G17*'⚙️ Настройки'!B16,G17*0.5))))
J18: =IF(G18="","",IF(F18="User1",G18,IF(F18="User2",0,IF(I18="Да",G18*'⚙️ Настройки'!B15,G18*0.5)))) | K18: =IF(G18="","",IF(F18="User2",G18,IF(F18="User1",0,IF(I18="Да",G18*'⚙️ Настройки'!B16,G18*0.5))))
J19: =IF(G19="","",IF(F19="User1",G19,IF(F19="User2",0,IF(I19="Да",G19*'⚙️ Настройки'!B15,G19*0.5)))) | K19: =IF(G19="","",IF(F19="User2",G19,IF(F19="User1",0,IF(I19="Да",G19*'⚙️ Настройки'!B16,G19*0.5))))
J20: =IF(G20="","",IF(F20="User1",G20,IF(F20="User2",0,IF(I20="Да",G20*'⚙️ Настройки'!B15,G20*0.5)))) | K20: =IF(G20="","",IF(F20="User2",G20,IF(F20="User1",0,IF(I20="Да",G20*'⚙️ Настройки'!B16,G20*0.5))))
J21: =IF(G21="","",IF(F21="User1",G21,IF(F21="User2",0,IF(I21="Да",G21*'⚙️ Настройки'!B15,G21*0.5)))) | K21: =IF(G21="","",IF(F21="User2",G21,IF(F21="User1",0,IF(I21="Да",G21*'⚙️ Настройки'!B16,G21*0.5))))
J22: =IF(G22="","",IF(F22="User1",G22,IF(F22="User2",0,IF(I22="Да",G22*'⚙️ Настройки'!B15,G22*0.5)))) | K22: =IF(G22="","",IF(F22="User2",G22,IF(F22="User1",0,IF(I22="Да",G22*'⚙️ Настройки'!B16,G22*0.5))))
J23: =IF(G23="","",IF(F23="User1",G23,IF(F23="User2",0,IF(I23="Да",G23*'⚙️ Настройки'!B15,G23*0.5)))) | K23: =IF(G23="","",IF(F23="User2",G23,IF(F23="User1",0,IF(I23="Да",G23*'⚙️ Настройки'!B16,G23*0.5))))
J24: =IF(G24="","",IF(F24="User1",G24,IF(F24="User2",0,IF(I24="Да",G24*'⚙️ Настройки'!B15,G24*0.5)))) | K24: =IF(G24="","",IF(F24="User2",G24,IF(F24="User1",0,IF(I24="Да",G24*'⚙️ Настройки'!B16,G24*0.5))))
J25: =IF(G25="","",IF(F25="User1",G25,IF(F25="User2",0,IF(I25="Да",G25*'⚙️ Настройки'!B15,G25*0.5)))) | K25: =IF(G25="","",IF(F25="User2",G25,IF(F25="User1",0,IF(I25="Да",G25*'⚙️ Настройки'!B16,G25*0.5))))
J26: =IF(G26="","",IF(F26="User1",G26,IF(F26="User2",0,IF(I26="Да",G26*'⚙️ Настройки'!B15,G26*0.5)))) | K26: =IF(G26="","",IF(F26="User2",G26,IF(F26="User1",0,IF(I26="Да",G26*'⚙️ Настройки'!B16,G26*0.5))))
J27: =IF(G27="","",IF(F27="User1",G27,IF(F27="User2",0,IF(I27="Да",G27*'⚙️ Настройки'!B15,G27*0.5)))) | K27: =IF(G27="","",IF(F27="User2",G27,IF(F27="User1",0,IF(I27="Да",G27*'⚙️ Настройки'!B16,G27*0.5))))
J28: =IF(G28="","",IF(F28="User1",G28,IF(F28="User2",0,IF(I28="Да",G28*'⚙️ Настройки'!B15,G28*0.5)))) | K28: =IF(G28="","",IF(F28="User2",G28,IF(F28="User1",0,IF(I28="Да",G28*'⚙️ Настройки'!B16,G28*0.5))))
J29: =IF(G29="","",IF(F29="User1",G29,IF(F29="User2",0,IF(I29="Да",G29*'⚙️ Настройки'!B15,G29*0.5)))) | K29: =IF(G29="","",IF(F29="User2",G29,IF(F29="User1",0,IF(I29="Да",G29*'⚙️ Настройки'!B16,G29*0.5))))
J30: =IF(G30="","",IF(F30="User1",G30,IF(F30="User2",0,IF(I30="Да",G30*'⚙️ Настройки'!B15,G30*0.5)))) | K30: =IF(G30="","",IF(F30="User2",G30,IF(F30="User1",0,IF(I30="Да",G30*'⚙️ Настройки'!B16,G30*0.5))))
J31: =IF(G31="","",IF(F31="User1",G31,IF(F31="User2",0,IF(I31="Да",G31*'⚙️ Настройки'!B15,G31*0.5)))) | K31: =IF(G31="","",IF(F31="User2",G31,IF(F31="User1",0,IF(I31="Да",G31*'⚙️ Настройки'!B16,G31*0.5))))
J32: =IF(G32="","",IF(F32="User1",G32,IF(F32="User2",0,IF(I32="Да",G32*'⚙️ Настройки'!B15,G32*0.5)))) | K32: =IF(G32="","",IF(F32="User2",G32,IF(F32="User1",0,IF(I32="Да",G32*'⚙️ Настройки'!B16,G32*0.5))))
J33: =IF(G33="","",IF(F33="User1",G33,IF(F33="User2",0,IF(I33="Да",G33*'⚙️ Настройки'!B15,G33*0.5)))) | K33: =IF(G33="","",IF(F33="User2",G33,IF(F33="User1",0,IF(I33="Да",G33*'⚙️ Настройки'!B16,G33*0.5))))
J34: =IF(G34="","",IF(F34="User1",G34,IF(F34="User2",0,IF(I34="Да",G34*'⚙️ Настройки'!B15,G34*0.5)))) | K34: =IF(G34="","",IF(F34="User2",G34,IF(F34="User1",0,IF(I34="Да",G34*'⚙️ Настройки'!B16,G34*0.5))))
J35: =IF(G35="","",IF(F35="User1",G35,IF(F35="User2",0,IF(I35="Да",G35*'⚙️ Настройки'!B15,G35*0.5)))) | K35: =IF(G35="","",IF(F35="User2",G35,IF(F35="User1",0,IF(I35="Да",G35*'⚙️ Настройки'!B16,G35*0.5))))
J36: =IF(G36="","",IF(F36="User1",G36,IF(F36="User2",0,IF(I36="Да",G36*'⚙️ Настройки'!B15,G36*0.5)))) | K36: =IF(G36="","",IF(F36="User2",G36,IF(F36="User1",0,IF(I36="Да",G36*'⚙️ Настройки'!B16,G36*0.5))))
J37: =IF(G37="","",IF(F37="User1",G37,IF(F37="User2",0,IF(I37="Да",G37*'⚙️ Настройки'!B15,G37*0.5)))) | K37: =IF(G37="","",IF(F37="User2",G37,IF(F37="User1",0,IF(I37="Да",G37*'⚙️ Настройки'!B16,G37*0.5))))
J38: =IF(G38="","",IF(F38="User1",G38,IF(F38="User2",0,IF(I38="Да",G38*'⚙️ Настройки'!B15,G38*0.5)))) | K38: =IF(G38="","",IF(F38="User2",G38,IF(F38="User1",0,IF(I38="Да",G38*'⚙️ Настройки'!B16,G38*0.5))))
J39: =IF(G39="","",IF(F39="User1",G39,IF(F39="User2",0,IF(I39="Да",G39*'⚙️ Настройки'!B15,G39*0.5)))) | K39: =IF(G39="","",IF(F39="User2",G39,IF(F39="User1",0,IF(I39="Да",G39*'⚙️ Настройки'!B16,G39*0.5))))
J40: =IF(G40="","",IF(F40="User1",G40,IF(F40="User2",0,IF(I40="Да",G40*'⚙️ Настройки'!B15,G40*0.5)))) | K40: =IF(G40="","",IF(F40="User2",G40,IF(F40="User1",0,IF(I40="Да",G40*'⚙️ Настройки'!B16,G40*0.5))))
...

Sheet 📊 Сводка
A1: 📊 СВОДКА ПО МЕСЯЦУ
A2: Выбери месяц → | B2: 2026-04 | C2: формат: YYYY-MM (например 2026-04)
A4: 💰 ДОХОДЫ | I4: Зарплата User1 | J4: 75000
A5: Доходы User1 | B5: 75000 | I5: 💼 РАСЧЁТ ЗАРПЛАТЫ ПО РАБОЧИМ ДНЯМ
A6: Доходы User2 | B6: =SUMIFS('📋 Транзакции'!G:G,'📋 Транзакции'!B:B,$B$2,'📋 Транзакции'!E:E,"Доход",'📋 Транзакции'!F:F,"User2") | I6: Расчётный месяц → | J6: 2026-04 | K6: ← введи нужный месяц (ГГГГ-ММ)
A7: ИТОГО ДОХОДЫ | B7: =SUM(B5:B6) | I7: Рабочих дней 1 – 15 | J7: =IFERROR(NETWORKDAYS(DATE(LEFT(J6,4)*1,RIGHT(J6,2)*1,1),DATE(LEFT(J6,4)*1,RIGHT(J6,2)*1,15)),0)
I8: Рабочих дней 16 – конец | J8: =IFERROR(NETWORKDAYS(DATE(LEFT(J6,4)*1,RIGHT(J6,2)*1,16),EOMONTH(DATE(LEFT(J6,4)*1,RIGHT(J6,2)*1,1),0)),0)
A9: 💸 РАСХОДЫ ПО КАТЕГОРИЯМ | B9: Всего | C9: User1 | D9: User2 | E9: Обязат. | F9: % дохода | I9: Итого рабочих дней | J9: =J7+J8
A10: Кредиты | B10: =IF(A10="","",SUMIFS('📋 Транзакции'!G:G,'📋 Транзакции'!B:B,$B$2,'📋 Транзакции'!D:D,A10,'📋 Транзакции'!E:E,"Расход")) | C10: =IF(A10="","",SUMIFS('📋 Транзакции'!J:J,'📋 Транзакции'!B:B,$B$2,'📋 Транзакции'!D:D,A10,'📋 Транзакции'!E:E,"Расход")) | D10: =IF(A10="","",SUMIFS('📋 Транзакции'!K:K,'📋 Транзакции'!B:B,$B$2,'📋 Транзакции'!D:D,A10,'📋 Транзакции'!E:E,"Расход")) | E10: =IF(A10="","",SUMIFS('📋 Транзакции'!G:G,'📋 Транзакции'!B:B,$B$2,'📋 Транзакции'!D:D,A10,'📋 Транзакции'!E:E,"Расход",'📋 Транзакции'!I:I,"Да")) | F10: =IFERROR(B10/B$7,"")
A11: Ипотека | B11: =IF(A11="","",SUMIFS('📋 Транзакции'!G:G,'📋 Транзакции'!B:B,$B$2,'📋 Транзакции'!D:D,A11,'📋 Транзакции'!E:E,"Расход")) | C11: =IF(A11="","",SUMIFS('📋 Транзакции'!J:J,'📋 Транзакции'!B:B,$B$2,'📋 Транзакции'!D:D,A11,'📋 Транзакции'!E:E,"Расход")) | D11: =IF(A11="","",SUMIFS('📋 Транзакции'!K:K,'📋 Транзакции'!B:B,$B$2,'📋 Транзакции'!D:D,A11,'📋 Транзакции'!E:E,"Расход")) | E11: =IF(A11="","",SUMIFS('📋 Транзакции'!G:G,'📋 Транзакции'!B:B,$B$2,'📋 Транзакции'!D:D,A11,'📋 Транзакции'!E:E,"Расход",'📋 Транзакции'!I:I,"Да")) | F11: =IFERROR(B11/B$7,"") | J11: 1-я зарплата (аванс) | K11: 2-я зарплата (остаток)
A12: Коммунальные | B12: =IF(A12="","",SUMIFS('📋 Транзакции'!G:G,'📋 Транзакции'!B:B,$B$2,'📋 Транзакции'!D:D,A12,'📋 Транзакции'!E:E,"Расход")) | C12: =IF(A12="","",SUMIFS('📋 Транзакции'!J:J,'📋 Транзакции'!B:B,$B$2,'📋 Транзакции'!D:D,A12,'📋 Транзакции'!E:E,"Расход")) | D12: =IF(A12="","",SUMIFS('📋 Транзакции'!K:K,'📋 Транзакции'!B:B,$B$2,'📋 Транзакции'!D:D,A12,'📋 Транзакции'!E:E,"Расход")) | E12: =IF(A12="","",SUMIFS('📋 Транзакции'!G:G,'📋 Транзакции'!B:B,$B$2,'📋 Транзакции'!D:D,A12,'📋 Транзакции'!E:E,"Расход",'📋 Транзакции'!I:I,"Да")) | F12: =IFERROR(B12/B$7,"") | I12: User1 | J12: =IFERROR(ROUND(J4*J7/J9,-2),0) | K12: =IFERROR(ROUND(J4*J8/J9,-2),0)
A13: Транспорт | B13: =IF(A13="","",SUMIFS('📋 Транзакции'!G:G,'📋 Транзакции'!B:B,$B$2,'📋 Транзакции'!D:D,A13,'📋 Транзакции'!E:E,"Расход")) | C13: =IF(A13="","",SUMIFS('📋 Транзакции'!J:J,'📋 Транзакции'!B:B,$B$2,'📋 Транзакции'!D:D,A13,'📋 Транзакции'!E:E,"Расход")) | D13: =IF(A13="","",SUMIFS('📋 Транзакции'!K:K,'📋 Транзакции'!B:B,$B$2,'📋 Транзакции'!D:D,A13,'📋 Транзакции'!E:E,"Расход")) | E13: =IF(A13="","",SUMIFS('📋 Транзакции'!G:G,'📋 Транзакции'!B:B,$B$2,'📋 Транзакции'!D:D,A13,'📋 Транзакции'!E:E,"Расход",'📋 Транзакции'!I:I,"Да")) | F13: =IFERROR(B13/B$7,"") | I13: User2 | J13: =IFERROR(ROUND(J4*J8/J10,-2),0) | K13: =IFERROR(ROUND(K4*K8/K10,-2),0)
A14: Бензин | B14: =IF(A14="","",SUMIFS('📋 Транзакции'!G:G,'📋 Транзакции'!B:B,$B$2,'📋 Транзакции'!D:D,A14,'📋 Транзакции'!E:E,"Расход")) | C14: =IF(A14="","",SUMIFS('📋 Транзакции'!J:J,'📋 Транзакции'!B:B,$B$2,'📋 Транзакции'!D:D,A14,'📋 Транзакции'!E:E,"Расход")) | D14: =IF(A14="","",SUMIFS('📋 Транзакции'!K:K,'📋 Транзакции'!B:B,$B$2,'📋 Транзакции'!D:D,A14,'📋 Транзакции'!E:E,"Расход")) | E14: =IF(A14="","",SUMIFS('📋 Транзакции'!G:G,'📋 Транзакции'!B:B,$B$2,'📋 Транзакции'!D:D,A14,'📋 Транзакции'!E:E,"Расход",'📋 Транзакции'!I:I,"Да")) | F14: =IFERROR(B14/B$7,"") | I14: ИТОГО семья | J14: =J12+J13 | K14: =K12+K13
A15: Дом | B15: =IF(A15="","",SUMIFS('📋 Транзакции'!G:G,'📋 Транзакции'!B:B,$B$2,'📋 Транзакции'!D:D,A15,'📋 Транзакции'!E:E,"Расход")) | C15: =IF(A15="","",SUMIFS('📋 Транзакции'!J:J,'📋 Транзакции'!B:B,$B$2,'📋 Транзакции'!D:D,A15,'📋 Транзакции'!E:E,"Расход")) | D15: =IF(A15="","",SUMIFS('📋 Транзакции'!K:K,'📋 Транзакции'!B:B,$B$2,'📋 Транзакции'!D:D,A15,'📋 Транзакции'!E:E,"Расход")) | E15: =IF(A15="","",SUMIFS('📋 Транзакции'!G:G,'📋 Транзакции'!B:B,$B$2,'📋 Транзакции'!D:D,A15,'📋 Транзакции'!E:E,"Расход",'📋 Транзакции'!I:I,"Да")) | F15: =IFERROR(B15/B$7,"") | I15: Проверка (= оклад семьи) | J15: =J14+K14
A16: Платежи/подписки | B16: =IF(A16="","",SUMIFS('📋 Транзакции'!G:G,'📋 Транзакции'!B:B,$B$2,'📋 Транзакции'!D:D,A16,'📋 Транзакции'!E:E,"Расход")) | C16: =IF(A16="","",SUMIFS('📋 Транзакции'!J:J,'📋 Транзакции'!B:B,$B$2,'📋 Транзакции'!D:D,A16,'📋 Транзакции'!E:E,"Расход")) | D16: =IF(A16="","",SUMIFS('📋 Транзакции'!K:K,'📋 Транзакции'!B:B,$B$2,'📋 Транзакции'!D:D,A16,'📋 Транзакции'!E:E,"Расход")) | E16: =IF(A16="","",SUMIFS('📋 Транзакции'!G:G,'📋 Транзакции'!B:B,$B$2,'📋 Транзакции'!D:D,A16,'📋 Транзакции'!E:E,"Расход",'📋 Транзакции'!I:I,"Да")) | F16: =IFERROR(B16/B$7,"")
A17: User1 личное | B17: =IF(A17="","",SUMIFS('📋 Транзакции'!G:G,'📋 Транзакции'!B:B,$B$2,'📋 Транзакции'!D:D,A17,'📋 Транзакции'!E:E,"Расход")) | C17: =IF(A17="","",SUMIFS('📋 Транзакции'!J:J,'📋 Транзакции'!B:B,$B$2,'📋 Транзакции'!D:D,A17,'📋 Транзакции'!E:E,"Расход")) | D17: =IF(A17="","",SUMIFS('📋 Транзакции'!K:K,'📋 Транзакции'!B:B,$B$2,'📋 Транзакции'!D:D,A17,'📋 Транзакции'!E:E,"Расход")) | E17: =IF(A17="","",SUMIFS('📋 Транзакции'!G:G,'📋 Транзакции'!B:B,$B$2,'📋 Транзакции'!D:D,A17,'📋 Транзакции'!E:E,"Расход",'📋 Транзакции'!I:I,"Да")) | F17: =IFERROR(B17/B$7,"")
A18: User2 личное | B18: =IF(A18="","",SUMIFS('📋 Транзакции'!G:G,'📋 Транзакции'!B:B,$B$2,'📋 Транзакции'!D:D,A18,'📋 Транзакции'!E:E,"Расход")) | C18: =IF(A18="","",SUMIFS('📋 Транзакции'!J:J,'📋 Транзакции'!B:B,$B$2,'📋 Транзакции'!D:D,A18,'📋 Транзакции'!E:E,"Расход")) | D18: =IF(A18="","",SUMIFS('📋 Транзакции'!K:K,'📋 Транзакции'!B:B,$B$2,'📋 Транзакции'!D:D,A18,'📋 Транзакции'!E:E,"Расход")) | E18: =IF(A18="","",SUMIFS('📋 Транзакции'!G:G,'📋 Транзакции'!B:B,$B$2,'📋 Транзакции'!D:D,A18,'📋 Транзакции'!E:E,"Расход",'📋 Транзакции'!I:I,"Да")) | F18: =IFERROR(B18/B$7,"")
A19: Развлечения | B19: =IF(A19="","",SUMIFS('📋 Транзакции'!G:G,'📋 Транзакции'!B:B,$B$2,'📋 Транзакции'!D:D,A19,'📋 Транзакции'!E:E,"Расход")) | C19: =IF(A19="","",SUMIFS('📋 Транзакции'!J:J,'📋 Транзакции'!B:B,$B$2,'📋 Транзакции'!D:D,A19,'📋 Транзакции'!E:E,"Расход")) | D19: =IF(A19="","",SUMIFS('📋 Транзакции'!K:K,'📋 Транзакции'!B:B,$B$2,'📋 Транзакции'!D:D,A19,'📋 Транзакции'!E:E,"Расход")) | E19: =IF(A19="","",SUMIFS('📋 Транзакции'!G:G,'📋 Транзакции'!B:B,$B$2,'📋 Транзакции'!D:D,A19,'📋 Транзакции'!E:E,"Расход",'📋 Транзакции'!I:I,"Да")) | F19: =IFERROR(B19/B$7,"")
A20: Подарки | B20: =IF(A20="","",SUMIFS('📋 Транзакции'!G:G,'📋 Транзакции'!B:B,$B$2,'📋 Транзакции'!D:D,A20,'📋 Транзакции'!E:E,"Расход")) | C20: =IF(A20="","",SUMIFS('📋 Транзакции'!J:J,'📋 Транзакции'!B:B,$B$2,'📋 Транзакции'!D:D,A20,'📋 Транзакции'!E:E,"Расход")) | D20: =IF(A20="","",SUMIFS('📋 Транзакции'!K:K,'📋 Транзакции'!B:B,$B$2,'📋 Транзакции'!D:D,A20,'📋 Транзакции'!E:E,"Расход")) | E20: =IF(A20="","",SUMIFS('📋 Транзакции'!G:G,'📋 Транзакции'!B:B,$B$2,'📋 Транзакции'!D:D,A20,'📋 Транзакции'!E:E,"Расход",'📋 Транзакции'!I:I,"Да")) | F20: =IFERROR(B20/B$7,"")
A21: Путешествия | B21: =IF(A21="","",SUMIFS('📋 Транзакции'!G:G,'📋 Транзакции'!B:B,$B$2,'📋 Транзакции'!D:D,A21,'📋 Транзакции'!E:E,"Расход")) | C21: =IF(A21="","",SUMIFS('📋 Транзакции'!J:J,'📋 Транзакции'!B:B,$B$2,'📋 Транзакции'!D:D,A21,'📋 Транзакции'!E:E,"Расход")) | D21: =IF(A21="","",SUMIFS('📋 Транзакции'!K:K,'📋 Транзакции'!B:B,$B$2,'📋 Транзакции'!D:D,A21,'📋 Транзакции'!E:E,"Расход")) | E21: =IF(A21="","",SUMIFS('📋 Транзакции'!G:G,'📋 Транзакции'!B:B,$B$2,'📋 Транзакции'!D:D,A21,'📋 Транзакции'!E:E,"Расход",'📋 Транзакции'!I:I,"Да")) | F21: =IFERROR(B21/B$7,"")
A22: Одежда | B22: =IF(A22="","",SUMIFS('📋 Транзакции'!G:G,'📋 Транзакции'!B:B,$B$2,'📋 Транзакции'!D:D,A22,'📋 Транзакции'!E:E,"Расход")) | C22: =IF(A22="","",SUMIFS('📋 Транзакции'!J:J,'📋 Транзакции'!B:B,$B$2,'📋 Транзакции'!D:D,A22,'📋 Транзакции'!E:E,"Расход")) | D22: =IF(A22="","",SUMIFS('📋 Транзакции'!K:K,'📋 Транзакции'!B:B,$B$2,'📋 Транзакции'!D:D,A22,'📋 Транзакции'!E:E,"Расход")) | E22: =IF(A22="","",SUMIFS('📋 Транзакции'!G:G,'📋 Транзакции'!B:B,$B$2,'📋 Транзакции'!D:D,A22,'📋 Транзакции'!E:E,"Расход",'📋 Транзакции'!I:I,"Да")) | F22: =IFERROR(B22/B$7,"")
F23: =IFERROR(B23/B$7,"")
B24: =IF(A24="","",SUMIFS('📋 Транзакции'!G:G,'📋 Транзакции'!B:B,$B$2,'📋 Транзакции'!D:D,A24,'📋 Транзакции'!E:E,"Расход")) | C24: =IF(A24="","",SUMIFS('📋 Транзакции'!J:J,'📋 Транзакции'!B:B,$B$2,'📋 Транзакции'!D:D,A24,'📋 Транзакции'!E:E,"Расход")) | D24: =IF(A24="","",SUMIFS('📋 Транзакции'!K:K,'📋 Транзакции'!B:B,$B$2,'📋 Транзакции'!D:D,A24,'📋 Транзакции'!E:E,"Расход")) | E24: =IF(A24="","",SUMIFS('📋 Транзакции'!G:G,'📋 Транзакции'!B:B,$B$2,'📋 Транзакции'!D:D,A24,'📋 Транзакции'!E:E,"Расход",'📋 Транзакции'!I:I,"Да")) | F24: =IFERROR(B24/B$7,"")
B25: =IF(A25="","",SUMIFS('📋 Транзакции'!G:G,'📋 Транзакции'!B:B,$B$2,'📋 Транзакции'!D:D,A25,'📋 Транзакции'!E:E,"Расход")) | C25: =IF(A25="","",SUMIFS('📋 Транзакции'!J:J,'📋 Транзакции'!B:B,$B$2,'📋 Транзакции'!D:D,A25,'📋 Транзакции'!E:E,"Расход")) | D25: =IF(A25="","",SUMIFS('📋 Транзакции'!K:K,'📋 Транзакции'!B:B,$B$2,'📋 Транзакции'!D:D,A25,'📋 Транзакции'!E:E,"Расход")) | E25: =IF(A25="","",SUMIFS('📋 Транзакции'!G:G,'📋 Транзакции'!B:B,$B$2,'📋 Транзакции'!D:D,A25,'📋 Транзакции'!E:E,"Расход",'📋 Транзакции'!I:I,"Да")) | F25: =IFERROR(B25/B$7,"")
B26: =IF(A26="","",SUMIFS('📋 Транзакции'!G:G,'📋 Транзакции'!B:B,$B$2,'📋 Транзакции'!D:D,A26,'📋 Транзакции'!E:E,"Расход")) | C26: =IF(A26="","",SUMIFS('📋 Транзакции'!J:J,'📋 Транзакции'!B:B,$B$2,'📋 Транзакции'!D:D,A26,'📋 Транзакции'!E:E,"Расход")) | D26: =IF(A26="","",SUMIFS('📋 Транзакции'!K:K,'📋 Транзакции'!B:B,$B$2,'📋 Транзакции'!D:D,A26,'📋 Транзакции'!E:E,"Расход")) | E26: =IF(A26="","",SUMIFS('📋 Транзакции'!G:G,'📋 Транзакции'!B:B,$B$2,'📋 Транзакции'!D:D,A26,'📋 Транзакции'!E:E,"Расход",'📋 Транзакции'!I:I,"Да")) | F26: =IFERROR(B26/B$7,"")
B27: =IF(A27="","",SUMIFS('📋 Транзакции'!G:G,'📋 Транзакции'!B:B,$B$2,'📋 Транзакции'!D:D,A27,'📋 Транзакции'!E:E,"Расход")) | C27: =IF(A27="","",SUMIFS('📋 Транзакции'!J:J,'📋 Транзакции'!B:B,$B$2,'📋 Транзакции'!D:D,A27,'📋 Транзакции'!E:E,"Расход")) | D27: =IF(A27="","",SUMIFS('📋 Транзакции'!K:K,'📋 Транзакции'!B:B,$B$2,'📋 Транзакции'!D:D,A27,'📋 Транзакции'!E:E,"Расход")) | E27: =IF(A27="","",SUMIFS('📋 Транзакции'!G:G,'📋 Транзакции'!B:B,$B$2,'📋 Транзакции'!D:D,A27,'📋 Транзакции'!E:E,"Расход",'📋 Транзакции'!I:I,"Да")) | F27: =IFERROR(B27/B$7,"")
B28: =IF(A28="","",SUMIFS('📋 Транзакции'!G:G,'📋 Транзакции'!B:B,$B$2,'📋 Транзакции'!D:D,A28,'📋 Транзакции'!E:E,"Расход")) | C28: =IF(A28="","",SUMIFS('📋 Транзакции'!J:J,'📋 Транзакции'!B:B,$B$2,'📋 Транзакции'!D:D,A28,'📋 Транзакции'!E:E,"Расход")) | D28: =IF(A28="","",SUMIFS('📋 Транзакции'!K:K,'📋 Транзакции'!B:B,$B$2,'📋 Транзакции'!D:D,A28,'📋 Транзакции'!E:E,"Расход")) | E28: =IF(A28="","",SUMIFS('📋 Транзакции'!G:G,'📋 Транзакции'!B:B,$B$2,'📋 Транзакции'!D:D,A28,'📋 Транзакции'!E:E,"Расход",'📋 Транзакции'!I:I,"Да")) | F28: =IFERROR(B28/B$7,"")
B29: =IF(A29="","",SUMIFS('📋 Транзакции'!G:G,'📋 Транзакции'!B:B,$B$2,'📋 Транзакции'!D:D,A29,'📋 Транзакции'!E:E,"Расход")) | C29: =IF(A29="","",SUMIFS('📋 Транзакции'!J:J,'📋 Транзакции'!B:B,$B$2,'📋 Транзакции'!D:D,A29,'📋 Транзакции'!E:E,"Расход")) | D29: =IF(A29="","",SUMIFS('📋 Транзакции'!K:K,'📋 Транзакции'!B:B,$B$2,'📋 Транзакции'!D:D,A29,'📋 Транзакции'!E:E,"Расход")) | E29: =IF(A29="","",SUMIFS('📋 Транзакции'!G:G,'📋 Транзакции'!B:B,$B$2,'📋 Транзакции'!D:D,A29,'📋 Транзакции'!E:E,"Расход",'📋 Транзакции'!I:I,"Да")) | F29: =IFERROR(B29/B$7,"")
B30: =IF(A30="","",SUMIFS('📋 Транзакции'!G:G,'📋 Транзакции'!B:B,$B$2,'📋 Транзакции'!D:D,A30,'📋 Транзакции'!E:E,"Расход")) | C30: =IF(A30="","",SUMIFS('📋 Транзакции'!J:J,'📋 Транзакции'!B:B,$B$2,'📋 Транзакции'!D:D,A30,'📋 Транзакции'!E:E,"Расход")) | D30: =IF(A30="","",SUMIFS('📋 Транзакции'!K:K,'📋 Транзакции'!B:B,$B$2,'📋 Транзакции'!D:D,A30,'📋 Транзакции'!E:E,"Расход")) | E30: =IF(A30="","",SUMIFS('📋 Транзакции'!G:G,'📋 Транзакции'!B:B,$B$2,'📋 Транзакции'!D:D,A30,'📋 Транзакции'!E:E,"Расход",'📋 Транзакции'!I:I,"Да")) | F30: =IFERROR(B30/B$7,"")
B31: =IF(A31="","",SUMIFS('📋 Транзакции'!G:G,'📋 Транзакции'!B:B,$B$2,'📋 Транзакции'!D:D,A31,'📋 Транзакции'!E:E,"Расход")) | C31: =IF(A31="","",SUMIFS('📋 Транзакции'!J:J,'📋 Транзакции'!B:B,$B$2,'📋 Транзакции'!D:D,A31,'📋 Транзакции'!E:E,"Расход")) | D31: =IF(A31="","",SUMIFS('📋 Транзакции'!K:K,'📋 Транзакции'!B:B,$B$2,'📋 Транзакции'!D:D,A31,'📋 Транзакции'!E:E,"Расход")) | E31: =IF(A31="","",SUMIFS('📋 Транзакции'!G:G,'📋 Транзакции'!B:B,$B$2,'📋 Транзакции'!D:D,A31,'📋 Транзакции'!E:E,"Расход",'📋 Транзакции'!I:I,"Да")) | F31: =IFERROR(B31/B$7,"")
B32: =IF(A32="","",SUMIFS('📋 Транзакции'!G:G,'📋 Транзакции'!B:B,$B$2,'📋 Транзакции'!D:D,A32,'📋 Транзакции'!E:E,"Расход")) | C32: =IF(A32="","",SUMIFS('📋 Транзакции'!J:J,'📋 Транзакции'!B:B,$B$2,'📋 Транзакции'!D:D,A32,'📋 Транзакции'!E:E,"Расход")) | D32: =IF(A32="","",SUMIFS('📋 Транзакции'!K:K,'📋 Транзакции'!B:B,$B$2,'📋 Транзакции'!D:D,A32,'📋 Транзакции'!E:E,"Расход")) | E32: =IF(A32="","",SUMIFS('📋 Транзакции'!G:G,'📋 Транзакции'!B:B,$B$2,'📋 Транзакции'!D:D,A32,'📋 Транзакции'!E:E,"Расход",'📋 Транзакции'!I:I,"Да")) | F32: =IFERROR(B32/B$7,"")
B33: =IF(A33="","",SUMIFS('📋 Транзакции'!G:G,'📋 Транзакции'!B:B,$B$2,'📋 Транзакции'!D:D,A33,'📋 Транзакции'!E:E,"Расход")) | C33: =IF(A33="","",SUMIFS('📋 Транзакции'!J:J,'📋 Транзакции'!B:B,$B$2,'📋 Транзакции'!D:D,A33,'📋 Транзакции'!E:E,"Расход")) | D33: =IF(A33="","",SUMIFS('📋 Транзакции'!K:K,'📋 Транзакции'!B:B,$B$2,'📋 Транзакции'!D:D,A33,'📋 Транзакции'!E:E,"Расход")) | E33: =IF(A33="","",SUMIFS('📋 Транзакции'!G:G,'📋 Транзакции'!B:B,$B$2,'📋 Транзакции'!D:D,A33,'📋 Транзакции'!E:E,"Расход",'📋 Транзакции'!I:I,"Да")) | F33: =IFERROR(B33/B$7,"")
B34: =IF(A34="","",SUMIFS('📋 Транзакции'!G:G,'📋 Транзакции'!B:B,$B$2,'📋 Транзакции'!D:D,A34,'📋 Транзакции'!E:E,"Расход")) | C34: =IF(A34="","",SUMIFS('📋 Транзакции'!J:J,'📋 Транзакции'!B:B,$B$2,'📋 Транзакции'!D:D,A34,'📋 Транзакции'!E:E,"Расход")) | D34: =IF(A34="","",SUMIFS('📋 Транзакции'!K:K,'📋 Транзакции'!B:B,$B$2,'📋 Транзакции'!D:D,A34,'📋 Транзакции'!E:E,"Расход")) | E34: =IF(A34="","",SUMIFS('📋 Транзакции'!G:G,'📋 Транзакции'!B:B,$B$2,'📋 Транзакции'!D:D,A34,'📋 Транзакции'!E:E,"Расход",'📋 Транзакции'!I:I,"Да")) | F34: =IFERROR(B34/B$7,"")
A35: ИТОГО РАСХОДЫ | B35: =SUM(B10:B34) | C35: =SUM(C10:C34) | D35: =SUM(D10:D34) | E35: =SUM(E10:E34) | F35: =IFERROR(SUM(B10:B34)/B7,0)
A37: 📈 ИТОГИ МЕСЯЦА
A38: Доходы | B38: =B7
A39: Расходы | B39: =B35
A40: Остаток | B40: =B38-B39
A41: Обязательные расходы | B41: =E35
A42: Рекомендую отложить (20%) | B42: =B40*'⚙️ Настройки'!B19
...

Sheet 📅 Платежи
A1: 📅 ОБЯЗАТЕЛЬНЫЕ ПЛАТЕЖИ — КАЖДЫЙ МЕСЯЦ
A2: 1️⃣ ПЕРВАЯ ЗАРПЛАТА — платежи до ~15-го числа
A3: Платёж / назначение | B3: День | C3: Сумма, ₽ | D3: Чья | E3: Обязат. | F3: Категория | G3: ✅ Статус
A4: Mortgage | B4: 5 | C4: 35000 | D4: Общее | E4: Да | F4: Ипотека | G4: ☐
A5: Internet | B5: 10 | C5: 900 | D5: Общее | E5: Да | F5: Коммунальные | G5: ☐
A6: Groceries reserve | B6: 12 | C6: 18000 | D6: Общее | E6: Да | F6: Еда и продукты | G6: ☐
A7: Fuel reserve | B7: 14 | C7: 6000 | D7: Общее | E7: Да | F7: Бензин | G7: ☐
A18: ИТОГО 1-я половина | B18: =SUM(C4:C17) | C18: =SUM(C4:C17)
A20: 2️⃣ ВТОРАЯ ЗАРПЛАТА — платежи с ~15-го по конец месяца
A21: Платёж / назначение | B21: День | C21: Сумма, ₽ | D21: Чья | E21: Обязат. | F21: Категория | G21: ✅ Статус
A22: Utilities | B22: 20 | C22: 7500 | D22: Общее | E22: Да | F22: Коммунальные | G22: ☐
A23: Mobile plans | B23: 22 | C23: 2400 | D23: Общее | E23: Да | F23: Платежи/подписки | G23: ☐
A24: Family groceries | B24: 24 | C24: 22000 | D24: Общее | E24: Да | F24: Еда и продукты | G24: ☐
A25: Education subscription | B25: 25 | C25: 3000 | D25: User2 | E25: Да | F25: Саморазвитие | G25: ☐
A34: ИТОГО 2-я половина | B34: =SUM(C22:C33) | C34: =SUM(C22:C33)
A36: 💰 ИТОГО ОБЯЗАТЕЛЬНЫХ В МЕСЯЦ | B36: =B34+B18 | C36: =C18+C34
A38: 💡 Столбец ✅ Статус — ставь «+» когда оплатил. Суммы в синих ячейках транзакций можно менять. День «~» = плавающая дата, платишь по ситуации.

Sheet 💳 Кредиты
A1: 💳 КРЕДИТЫ И ДОЛГИ
A2: Название | B2: Тип | C2: Остаток долга | D2: Ежемес. платёж | E2: Ставка % год. | F2: Дата открытия | G2: Дата закрытия | H2: Переплата план.
A3: Mortgage | B3: Ипотека | C3: 3200000 | D3: 35000 | E3: 0.08 | F3: 45306 | G3: 52611 | H3: =IFERROR(D3*(DATEDIF(F3,G3,"M"))-C3,0)
A4: Car loan | B4: Кредит | C4: 650000 | D4: 22000 | E4: 0.12 | F4: 45809 | G4: 47270 | H4: =IFERROR(D4*(DATEDIF(F4,G4,"M"))-C4,0)
A9: ИТОГО ДОЛГ | C9: =SUM(C3:C8) | D9: =SUM(D3:D8)
A11: 💡 Остатки долгов — обновлять вручную раз в месяц (синие ячейки)

Sheet 📈 Капитал
A1: 📈 ДИНАМИКА КАПИТАЛА
A2: Месяц | B2: Счета руб | C2: Счета USD→руб | D2: Инвестиции | E2: Крипта→руб | F2: Итого активы | G2: Долги (−) | H2: Чистый капитал | I2: Δ к прошлому | J2: Δ % | K2: Примечание | L2: ЗП 5 ого числа | M2: ЗП 20 числа | N2: Коэфф зп | O2: Коэфф аванса (20 число)
A3: 2026-01 | B3: 250000 | C3: 0 | D3: 150000 | E3: 0 | F3: =B3+C3+D3+E3 | G3: ='💳 Кредиты'!C9 | H3: =F3-G3 | I3: =0 | J3: =0 | K3: Example starting balance
A4: 2026-02 | C4: 0 | D4: 0 | E4: 0 | F4: =B4+C4+D4+E4 | H4: =F4-G4 | I4: =H4-H3 | J4: =IFERROR(I4/H3,0)
A5: 2026-03 | C5: 0 | D5: 0 | E5: 0 | F5: =B5+C5+D5+E5 | H5: =F5-G5 | I5: =H5-H4 | J5: =IFERROR(I5/H4,0)
A6: 2026-04 | C6: 0 | D6: 0 | E6: 0 | F6: =B6+C6+D6+E6 | H6: =F6-G6 | I6: =H6-H5 | J6: =IFERROR(I6/H5,0)
A7: 2026-05 | C7: 0 | D7: 0 | E7: 0 | F7: =B7+C7+D7+E7 | H7: =F7-G7 | I7: =H7-H6 | J7: =IFERROR(I7/H6,0)
A8: 2026-06 | C8: 0 | D8: 0 | E8: 0 | F8: =B8+C8+D8+E8 | H8: =F8-G8 | I8: =H8-H7 | J8: =IFERROR(I8/H7,0)
A9: 2026-07 | C9: 0 | D9: 0 | E9: 0 | F9: =B9+C9+D9+E9 | H9: =F9-G9 | I9: =H9-H8 | J9: =IFERROR(I9/H8,0)
A10: 2026-08 | C10: 0 | D10: 0 | E10: 0 | F10: =B10+C10+D10+E10 | H10: =F10-G10 | I10: =H10-H9 | J10: =IFERROR(I10/H9,0)
A11: 2026-09 | C11: 0 | D11: 0 | E11: 0 | F11: =B11+C11+D11+E11 | H11: =F11-G11 | I11: =H11-H10 | J11: =IFERROR(I11/H10,0)
A12: 2026-10 | C12: 0 | D12: 0 | E12: 0 | F12: =B12+C12+D12+E12 | H12: =F12-G12 | I12: =H12-H11 | J12: =IFERROR(I12/H11,0)
A13: 2026-11 | C13: 0 | D13: 0 | E13: 0 | F13: =B13+C13+D13+E13 | H13: =F13-G13 | I13: =H13-H12 | J13: =IFERROR(I13/H12,0)
A14: 2026-12 | C14: 0 | D14: 0 | E14: 0 | F14: =B14+C14+D14+E14 | H14: =F14-G14 | I14: =H14-H13 | J14: =IFERROR(I14/H13,0)
A15: 2027-01 | C15: 0 | D15: 0 | E15: 0 | F15: =B15+C15+D15+E15 | H15: =F15-G15 | I15: =H15-H14 | J15: =IFERROR(I15/H14,0)
... A26: 2027-12 | C26: 0 | D26: 0 | E26: 0 | F26: =B26+C26+D26+E26 | H26: =F26-G26 | I26: =H26-H25 | J26: =IFERROR(I26/H25,0)
